Workbook

Sheet finalResultsImport
A1: Sample | B1: NPOC | C1: TN
A2: R1 | B2: 83.064129 | C2: 10.100821
A3: R2 | B3: 79.09267 | C3: 10.029426
A4: R3 | B4: 77.219341 | C4: 10.843323
A5: R4 | B5: 80.732874 | C5: 12.506812
A6: R5 | B6: 330.84319 | C6: 14.277393
A7: R6 | B7: 106.45993 | C7: 13.142222
A8: R7 | B8: 145.17541 | C8: 14.091768
A9: R8 | B9: 214.94653 | C9: 17.297377
A10: R9 | B10: 231.26532 | C10: 19.139352
A11: R10 | B11: 236.01108 | C11: 21.795224
A12: R11 | B12: 227.68518 | C12: 18.346874
A13: R12 | B13: 386.37701 | C13: 28.513438
... A73: R72 | B73: 74.699365 | C73: 65.969024

Sheet Final Results
C1: Data Provided by:
C2: SOEST Laboratory for
C3: Analtyical Biogeochemistry (S-LAB)
C4: University of Hawaii at Manoa
C5: 1000 Pope Rd
C6: Honolulu, HI 96822
C7: 808-956-5878
C9: Date Samples Received: | E9: 45996
C11: Project: | D11: Wall
A13: Sample | B13: NPOC (mg/L) | C13: TN (mg/L) | E13: Sample | F13: NPOC (uM) | G13: TN (uM)
A14: ='Run File 05.20.26'!A17 -> R1 | B14: ='Run File 05.20.26'!B17 -> 0.99765833 | C14: ='Run File 05.20.26'!C17 -> 0.14147917 | E14: =A14 -> R1 | F14: =B14/12.0107*1000 -> 83.064129 | G14: =C14/14.0067*1000 -> 10.100821
A15: ='Run File 05.20.26'!A18 -> R2 | B15: ='Run File 05.20.26'!B18 -> 0.94995833 | C15: ='Run File 05.20.26'!C18 -> 0.14047917 | E15: =A15 -> R2 | F15: =B15/12.0107*1000 -> 79.09267 | G15: =C15/14.0067*1000 -> 10.029426
A16: ='Run File 05.20.26'!A19 -> R3 | B16: ='Run File 05.20.26'!B19 -> 0.92745833 | C16: ='Run File 05.20.26'!C19 -> 0.15187917 | E16: =A16 -> R3 | F16: =B16/12.0107*1000 -> 77.219341 | G16: =C16/14.0067*1000 -> 10.843323
A17: ='Run File 05.20.26'!A20 -> R4 | B17: ='Run File 05.20.26'!B20 -> 0.96965833 | C17: ='Run File 05.20.26'!C20 -> 0.17517917 | E17: =A17 -> R4 | F17: =B17/12.0107*1000 -> 80.732874 | G17: =C17/14.0067*1000 -> 12.506812
A18: ='Run File 05.20.26'!A21 -> R5 | B18: ='Run File 05.20.26'!B21 -> 3.9736583 | C18: ='Run File 05.20.26'!C21 -> 0.19997917 | E18: =A18 -> R5 | F18: =B18/12.0107*1000 -> 330.84319 | G18: =C18/14.0067*1000 -> 14.277393
A19: ='Run File 05.20.26'!A22 -> R6 | B19: ='Run File 05.20.26'!B22 -> 1.2786583 | C19: ='Run File 05.20.26'!C22 -> 0.18407917 | E19: =A19 -> R6 | F19: =B19/12.0107*1000 -> 106.45993 | G19: =C19/14.0067*1000 -> 13.142222
A20: ='Run File 05.20.26'!A23 -> R7 | B20: ='Run File 05.20.26'!B23 -> 1.7436583 | C20: ='Run File 05.20.26'!C23 -> 0.19737917 | E20: =A20 -> R7 | F20: =B20/12.0107*1000 -> 145.17541 | G20: =C20/14.0067*1000 -> 14.091768
A21: ='Run File 05.20.26'!A24 -> R8 | B21: ='Run File 05.20.26'!B24 -> 2.5816583 | C21: ='Run File 05.20.26'!C24 -> 0.24227917 | E21: =A21 -> R8 | F21: =B21/12.0107*1000 -> 214.94653 | G21: =C21/14.0067*1000 -> 17.297377
A22: ='Run File 05.20.26'!A25 -> R9 | B22: ='Run File 05.20.26'!B25 -> 2.7776583 | C22: ='Run File 05.20.26'!C25 -> 0.26807917 | E22: =A22 -> R9 | F22: =B22/12.0107*1000 -> 231.26532 | G22: =C22/14.0067*1000 -> 19.139352
A23: ='Run File 05.20.26'!A26 -> R10 | B23: ='Run File 05.20.26'!B26 -> 2.8346583 | C23: ='Run File 05.20.26'!C26 -> 0.30527917 | E23: =A23 -> R10 | F23: =B23/12.0107*1000 -> 236.01108 | G23: =C23/14.0067*1000 -> 21.795224
A24: ='Run File 05.20.26'!A30 -> R11 | B24: ='Run File 05.20.26'!B30 -> 2.7346583 | C24: ='Run File 05.20.26'!C30 -> 0.25697917 | E24: =A24 -> R11 | F24: =B24/12.0107*1000 -> 227.68518 | G24: =C24/14.0067*1000 -> 18.346874
A25: ='Run File 05.20.26'!A31 -> R12 | B25: ='Run File 05.20.26'!B31 -> 4.6406583 | C25: ='Run File 05.20.26'!C31 -> 0.39937917 | E25: =A25 -> R12 | F25: =B25/12.0107*1000 -> 386.37701 | G25: =C25/14.0067*1000 -> 28.513438
A26: ='Run File 05.20.26'!A32 -> R13 | B26: ='Run File 05.26.26'!B18 -> 8.9426583 | C26: ='Run File 05.20.26'!C32 -> 0.71767917 | E26: =A26 -> R13 | F26: =B26/12.0107*1000 -> 744.55763 | G26: =C26/14.0067*1000 -> 51.238276
A27: ='Run File 05.20.26'!A33 -> R14 | B27: ='Run File 05.26.26'!B17 -> 10.523392 | C27: ='Run File 05.20.26'!C33 -> 0.85060833 | E27: =A27 -> R14 | F27: =B27/12.0107*1000 -> 876.16806 | G27: =C27/14.0067*1000 -> 60.728675
A28: ='Run File 05.20.26'!A34 -> R15 | B28: ='Run File 05.20.26'!B34 -> 1.1416583 | C28: ='Run File 05.20.26'!C34 -> 0.16937917 | E28: =A28 -> R15 | F28: =B28/12.0107*1000 -> 95.053438 | G28: =C28/14.0067*1000 -> 12.092725
A29: ='Run File 05.20.26'!A35 -> R16 | B29: ='Run File 05.20.26'!B35 -> 1.0636583 | C29: ='Run File 05.20.26'!C35 -> 0.15297917 | E29: =A29 -> R16 | F29: =B29/12.0107*1000 -> 88.559229 | G29: =C29/14.0067*1000 -> 10.921856
A30: ='Run File 05.20.26'!A36 -> R17 | B30: ='Run File 05.20.26'!B36 -> 1.0766583 | C30: ='Run File 05.20.26'!C36 -> 0.15217917 | E30: =A30 -> R17 | F30: =B30/12.0107*1000 -> 89.641597 | G30: =C30/14.0067*1000 -> 10.864741
A31: ='Run File 05.20.26'!A37 -> R18 | B31: ='Run File 05.20.26'!B37 -> 1.7446583 | C31: ='Run File 05.20.26'!C37 -> 0.22957917 | E31: =A31 -> R18 | F31: =B31/12.0107*1000 -> 145.25867 | G31: =C31/14.0067*1000 -> 16.390668
A32: ='Run File 05.20.26'!A38 -> R19 | B32: ='Run File 05.20.26'!B38 -> 2.1446583 | C32: ='Run File 05.20.26'!C38 -> 0.25337917 | E32: =A32 -> R19 | F32: =B32/12.0107*1000 -> 178.56231 | G32: =C32/14.0067*1000 -> 18.089855
A33: ='Run File 05.20.26'!A39 -> R20 | B33: ='Run File 05.20.26'!B39 -> 2.4916583 | C33: ='Run File 05.20.26'!C39 -> 0.30767917 | E33: =A33 -> R20 | F33: =B33/12.0107*1000 -> 207.45322 | G33: =C33/14.0067*1000 -> 21.966571
A34: ='Run File 05.20.26'!A43 -> R21 | B34: ='Run File 05.20.26'!B43 -> 2.5996583 | C34: ='Run File 05.20.26'!C43 -> 0.30017917 | E34: =A34 -> R21 | F34: =B34/12.0107*1000 -> 216.4452 | G34: =C34/14.0067*1000 -> 21.431113
A35: ='Run File 05.20.26'!A44 -> R22 | B35: ='Run File 05.20.26'!B44 -> 2.5966583 | C35: ='Run File 05.20.26'!C44 -> 0.30517917 | E35: =A35 -> R22 | F35: =B35/12.0107*1000 -> 216.19542 | G35: =C35/14.0067*1000 -> 21.788085
A36: ='Run File 05.20.26'!A45 -> R23 | B36: ='Run File 05.20.26'!B45 -> 4.6216583 | C36: ='Run File 05.20.26'!C45 -> 0.51307917 | E36: =A36 -> R23 | F36: =B36/12.0107*1000 -> 384.79509 | G36: =C36/14.0067*1000 -> 36.630981
A37: ='Run File 05.20.26'!A46 -> R24 | B37: ='Run File 05.26.26'!B19 -> 8.8836583 | C37: ='Run File 05.20.26'!C46 -> 0.95167917 | E37: =A37 -> R24 | F37: =B37/12.0107*1000 -> 739.64534 | G37: =C37/14.0067*1000 -> 67.944567
A38: ='Run File 05.20.26'!A47 -> R25 | B38: ='Run File 05.26.26'!B20 -> 11.513658 | C38: ='Run File 05.20.26'!C47 -> 1.2752792 | E38: =A38 -> R25 | F38: =B38/12.0107*1000 -> 958.61676 | G38: =C38/14.0067*1000 -> 91.047796
A39: ='Run File 05.20.26'!A48 -> R26 | B39: ='Run File 05.20.26'!B48 -> 1.0186583 | C39: ='Run File 05.20.26'!C48 -> 0.18657917 | E39: =A39 -> R26 | F39: =B39/12.0107*1000 -> 84.81257 | G39: =C39/14.0067*1000 -> 13.320708
A40: ='Run File 05.20.26'!A49 -> R27 | B40: ='Run File 05.20.26'!B49 -> 1.0366583 | C40: ='Run File 05.20.26'!C49 -> 0.20307917 | E40: =A40 -> R27 | F40: =B40/12.0107*1000 -> 86.311234 | G40: =C40/14.0067*1000 -> 14.498716
A41: ='Run File 05.20.26'!A50 -> R28 | B41: ='Run File 05.20.26'!B50 -> 1.0576583 | C41: ='Run File 05.20.26'!C50 -> 0.22327917 | E41: =A41 -> R28 | F41: =B41/12.0107*1000 -> 88.059675 | G41: =C41/14.0067*1000 -> 15.940883
A42: ='Run File 05.20.26'!A51 -> R29 | B42: ='Run File 05.20.26'!B51 -> 0.98165833 | C42: ='Run File 05.20.26'!C51 -> 0.20497917 | E42: =A42 -> R29 | F42: =B42/12.0107*1000 -> 81.731983 | G42: =C42/14.0067*1000 -> 14.634365
A43: ='Run File 05.20.26'!A52 -> R30 | B43: ='Run File 05.20.26'!B52 -> 0.96865833 | C43: ='Run File 05.20.26'!C52 -> 0.27467917 | E43: =A43 -> R30 | F43: =B43/12.0107*1000 -> 80.649615 | G43: =C43/14.0067*1000 -> 19.610555
...

Sheet Run File 05.20.26
A1: System | B1: TOCReg | D1: Deep Seawater Reference Material
A2: S/W Version | B2: 1
A3: User | B3: A.Whitworth | D3: NPOC certified reference value 0.504-0.516 mg/L: 42-43 uM
A4: Date | B4: 46162 | D4: TN certified reference value 0.434-0.448 mg/L: 31-32 uM
A5: Comments | B5: Wall (12/5/26)
A9: Standards
A10: Range | B10: 0-5mg/L
A12: Raw data (mg/L) | E12: Unit conversion
A13: Sample | B13: NPOC (mg/L) | C13: TN (mg/L) | E13: Sample | F13: NPOC (uM) | G13: TN (uM)
A14: DIW | B14: -0.0023 | C14: 0 | E14: =A14 -> DIW | F14: =B14/12.0107*1000 -> -0.19149592 | G14: =C14/14.0067*1000 -> 0
A15: LNSW | B15: 0.9383 | C15: 0.05402 | E15: =A15 -> LNSW | F15: =B15/12.0107*1000 -> 78.122008 | G15: =C15/14.0067*1000 -> 3.8567257
A16: DSWR [B24,L05-24] | B16: 0.51515833 | C16: 0.44307917 | E16: =A16 -> DSWR [B24,L05-24] | F16: =B16/12.0107*1000 -> 42.891616 | G16: =C16/14.0067*1000 -> 31.633373
A17: R1 | B17: 0.99765833 | C17: 0.14147917 | E17: =A17 -> R1 | F17: =B17/12.0107*1000 -> 83.064129 | G17: =C17/14.0067*1000 -> 10.100821
A18: R2 | B18: 0.94995833 | C18: 0.14047917 | E18: =A18 -> R2 | F18: =B18/12.0107*1000 -> 79.09267 | G18: =C18/14.0067*1000 -> 10.029426
A19: R3 | B19: 0.92745833 | C19: 0.15187917 | E19: =A19 -> R3 | F19: =B19/12.0107*1000 -> 77.219341 | G19: =C19/14.0067*1000 -> 10.843323
A20: R4 | B20: 0.96965833 | C20: 0.17517917 | E20: =A20 -> R4 | F20: =B20/12.0107*1000 -> 80.732874 | G20: =C20/14.0067*1000 -> 12.506812
A21: R5 | B21: 3.9736583 | C21: 0.19997917 | E21: =A21 -> R5 | F21: =B21/12.0107*1000 -> 330.84319 | G21: =C21/14.0067*1000 -> 14.277393
A22: R6 | B22: 1.2786583 | C22: 0.18407917 | E22: =A22 -> R6 | F22: =B22/12.0107*1000 -> 106.45993 | G22: =C22/14.0067*1000 -> 13.142222
A23: R7 | B23: 1.7436583 | C23: 0.19737917 | E23: =A23 -> R7 | F23: =B23/12.0107*1000 -> 145.17541 | G23: =C23/14.0067*1000 -> 14.091768
A24: R8 | B24: 2.5816583 | C24: 0.24227917 | E24: =A24 -> R8 | F24: =B24/12.0107*1000 -> 214.94653 | G24: =C24/14.0067*1000 -> 17.297377
A25: R9 | B25: 2.7776583 | C25: 0.26807917 | E25: =A25 -> R9 | F25: =B25/12.0107*1000 -> 231.26532 | G25: =C25/14.0067*1000 -> 19.139352
... A31: R12 | B31: 4.6406583 | C31: 0.39937917 | E31: =A31 -> R12 | F31: =B31/12.0107*1000 -> 386.37701 | G31: =C31/14.0067*1000 -> 28.513438
A32: R13 | C32: 0.71767917 | E32: =A32 -> R13 | G32: =C32/14.0067*1000 -> 51.238276
A33: R14 | C33: 0.85060833
A34: R15 | B34: 1.1416583 | C34: 0.16937917 | E34: =A34 -> R15 | F34: =B34/12.0107*1000 -> 95.053438 | G34: =C34/14.0067*1000 -> 12.092725
A35: R16 | B35: 1.0636583 | C35: 0.15297917 | E35: =A35 -> R16 | F35: =B35/12.0107*1000 -> 88.559229 | G35: =C35/14.0067*1000 -> 10.921856
A36: R17 | B36: 1.0766583 | C36: 0.15217917 | E36: =A36 -> R17 | F36: =B36/12.0107*1000 -> 89.641597 | G36: =C36/14.0067*1000 -> 10.864741
A37: R18 | B37: 1.7446583 | C37: 0.22957917 | E37: =A37 -> R18 | F37: =B37/12.0107*1000 -> 145.25867 | G37: =C37/14.0067*1000 -> 16.390668
A38: R19 | B38: 2.1446583 | C38: 0.25337917 | E38: =A38 -> R19 | F38: =B38/12.0107*1000 -> 178.56231 | G38: =C38/14.0067*1000 -> 18.089855
A39: R20 | B39: 2.4916583 | C39: 0.30767917 | E39: =A39 -> R20 | F39: =B39/12.0107*1000 -> 207.45322 | G39: =C39/14.0067*1000 -> 21.966571
A40: DIW | B40: -0.00045 | C40: 0 | E40: =A40 -> DIW | F40: =B40/12.0107*1000 -> -0.037466592 | G40: =C40/14.0067*1000 -> 0
A41: LNSW | B41: 0.9518 | C41: 0.06093 | E41: =A41 -> LNSW | F41: =B41/12.0107*1000 -> 79.246006 | G41: =C41/14.0067*1000 -> 4.350061
A42: DSWR [B24,L05-24] | B42: 0.51065833 | C42: 0.43917917 | E42: =A42 -> DSWR [B24,L05-24] | F42: =B42/12.0107*1000 -> 42.51695 | G42: =C42/14.0067*1000 -> 31.354935
A43: R21 | B43: 2.5996583 | C43: 0.30017917 | E43: =A43 -> R21 | F43: =B43/12.0107*1000 -> 216.4452 | G43: =C43/14.0067*1000 -> 21.431113
A44: R22 | B44: 2.5966583 | C44: 0.30517917 | E44: =A44 -> R22 | F44: =B44/12.0107*1000 -> 216.19542 | G44: =C44/14.0067*1000 -> 21.788085
A45: R23 | B45: 4.6216583 | C45: 0.51307917 | E45: =A45 -> R23 | F45: =B45/12.0107*1000 -> 384.79509 | G45: =C45/14.0067*1000 -> 36.630981
A46: R24 | C46: 0.95167917 | E46: =A46 -> R24 | G46: =C46/14.0067*1000 -> 67.944567
A47: R25 | C47: 1.2752792 | E47: =A47 -> R25 | G47: =C47/14.0067*1000 -> 91.047796
A48: R26 | B48: 1.0186583 | C48: 0.18657917 | E48: =A48 -> R26 | F48: =B48/12.0107*1000 -> 84.81257 | G48: =C48/14.0067*1000 -> 13.320708
A49: R27 | B49: 1.0366583 | C49: 0.20307917 | E49: =A49 -> R27 | F49: =B49/12.0107*1000 -> 86.311234 | G49: =C49/14.0067*1000 -> 14.498716
...

Sheet Run File 05.26.26
A1: System | B1: TOCReg | D1: Deep Seawater Reference Material
A2: S/W Version | B2: 1
A3: User | B3: A.Whitworth | D3: NPOC certified reference value 0.504-0.516 mg/L: 42-43 uM
A4: Date | B4: 46168 | D4: TN certified reference value 0.434-0.448 mg/L: 31-32 uM
A5: Comments | B5: Wall (12/5/25)
F6: *Highlighted samples were analyzed with a dilution. The dilution has been applied to reported results
A9: Standards
A10: Range | B10: 0-5mg/L
A12: Raw data (mg/L) | E12: Unit conversion
A13: Sample | B13: NPOC (mg/L) | C13: TN (mg/L) | E13: Sample | F13: NPOC (uM) | G13: TN (uM)
A14: DIW | B14: 0.01018 | C14: 0 | E14: =A14 -> DIW | F14: =B14/12.0107*1000 -> 0.84757758 | G14: =C14/14.0067*1000 -> 0
A15: LNSW | B15: 0.9531 | C15: 0.05637 | E15: =A15 -> LNSW | F15: =B15/12.0107*1000 -> 79.354242 | G15: =C15/14.0067*1000 -> 4.0245026
A16: DSWR [B24,L05-24] | B16: 0.51399167 | C16: 0.43560833 | E16: =A16 -> DSWR [B24,L05-24] | F16: =B16/12.0107*1000 -> 42.79448 | G16: =C16/14.0067*1000 -> 31.099997
A17: R14 | B17: 10.523392 | E17: =A17 -> R14 | F17: =B17/12.0107*1000 -> 876.16806
A18: R13 | B18: 8.9426583 | E18: =A18 -> R13 | F18: =B18/12.0107*1000 -> 744.55763
A19: R24 | B19: 8.8836583 | E19: =A19 -> R24 | F19: =B19/12.0107*1000 -> 739.64534
A20: R25 | B20: 11.513658 | E20: =A20 -> R25 | F20: =B20/12.0107*1000 -> 958.61676
A21: R50 | B21: 6.2786583 | E21: =A21 -> R50 | F21: =B21/12.0107*1000 -> 522.7554
A22: R51 | B22: 0.99139167 | C22: 0.18330833 | E22: =A22 -> R51 | F22: =B22/12.0107*1000 -> 82.542372 | G22: =C22/14.0067*1000 -> 13.087189
A23: R52 | B23: 1.1313917 | C23: 0.19070833 | E23: =A23 -> R52 | F23: =B23/12.0107*1000 -> 94.198645 | G23: =C23/14.0067*1000 -> 13.615508
A24: R53 | B24: 1.0183917 | C24: 0.16360833 | E24: =A24 -> R53 | F24: =B24/12.0107*1000 -> 84.790367 | G24: =C24/14.0067*1000 -> 11.680719
A25: R54 | B25: 4.5733917 | C25: 0.21310833 | E25: =A25 -> R54 | F25: =B25/12.0107*1000 -> 380.77645 | G25: =C25/14.0067*1000 -> 15.214742
A26: R55 | B26: 1.5113917 | C26: 0.22390833 | E26: =A26 -> R55 | F26: =B26/12.0107*1000 -> 125.8371 | G26: =C26/14.0067*1000 -> 15.985802
A27: DIW | B27: -0.00456 | C27: 0 | E27: =A27 -> DIW | F27: =B27/12.0107*1000 -> -0.37966147 | G27: =C27/14.0067*1000 -> 0
A28: LNSW | B28: 0.9486 | C28: 0.06335 | E28: =A28 -> LNSW | F28: =B28/12.0107*1000 -> 78.979577 | G28: =C28/14.0067*1000 -> 4.5228355
A29: DSWR [B24,L05-24] | B29: 0.50969167 | C29: 0.44550833 | E29: =A29 -> DSWR [B24,L05-24] | F29: =B29/12.0107*1000 -> 42.436466 | G29: =C29/14.0067*1000 -> 31.806802
A30: R56 | B30: 1.5953917 | C30: 0.23780833 | E30: =A30 -> R56 | F30: =B30/12.0107*1000 -> 132.83086 | G30: =C30/14.0067*1000 -> 16.978184
A31: R57 | B31: 1.6713917 | C31: 0.25880833 | E31: =A31 -> R57 | F31: =B31/12.0107*1000 -> 139.15856 | G31: =C31/14.0067*1000 -> 18.477467
A32: R58 | B32: 1.6113917 | C32: 0.24380833 | E32: =A32 -> R58 | F32: =B32/12.0107*1000 -> 134.16301 | G32: =C32/14.0067*1000 -> 17.406551
A33: R59 | B33: 2.1893917 | C33: 0.32680833 | E33: =A33 -> R59 | F33: =B33/12.0107*1000 -> 182.28677 | G33: =C33/14.0067*1000 -> 23.332286
... A52: DSWR [B24, L05-24] | B52: 0.51059167 | C52: 0.44080833 | E52: =A52 -> DSWR [B24, L05-24] | F52: =B52/12.0107*1000 -> 42.5114 | G52: =C52/14.0067*1000 -> 31.471248
